<?xml version="1.0" encoding="utf-8"?>
<!-- This URDF was automatically created by SolidWorks to URDF Exporter! Originally created by Stephen Brawner (brawner@gmail.com) 
     Commit Version: 1.6.0-4-g7f85cfe  Build Version: 1.6.7995.38578
     For more information, please see http://wiki.ros.org/sw_urdf_exporter -->
<robot
  name="dual_arms">
  <link
    name="base_link">
    <visual>
      <origin
        xyz="0 0 0"
        rpy="0 0 0" />
      <geometry>
        <mesh
          filename="package://duco_support/meshes/dual_gcr5/base_link.stl" />
      </geometry>
      <material
        name="">
        <color
          rgba="0.73333 0.78039 0.83922 1" />
      </material>
    </visual>
    <collision>
      <origin
        xyz="0 0 0"
        rpy="0 0 0" />
      <geometry>
        <mesh
          filename="package://duco_support/meshes/dual_gcr5/base_link.stl" />
      </geometry>
    </collision>
  </link>

<link
  name="arm_1_link_base">
  <inertial>
    <origin
      xyz="0.000021 0.004967 -0.01790"
      rpy="0 0 0" />
    <mass
      value="4.657" />
    <inertia
      ixx="1.0752E-05"
      ixy="7.523E-09"
      ixz="1.0743E-08"
      iyy="1.0133197E-05"
      iyz="4.49349E-07"
      izz="7.870754E-05" />
  </inertial>
  <visual>
    <origin
      xyz="0 0 0"
      rpy="0 0 0" />
    <geometry>
      <mesh
        filename="package://duco_support/meshes/dual_gcr5/base_link.stl" />
    </geometry>
    <material
      name="">
      <color
        rgba="0.79216 0.81961 0.93333 1" />
    </material>
  </visual>
  <collision>
    <origin
      xyz="0 0 0"
      rpy="0 0 0" />
    <geometry>
      <mesh
        filename="package://duco_support/meshes/dual_gcr5/base_link.stl" />
    </geometry>
  </collision>
</link>
<joint
  name="arm_1_joint_base"
  type="fixed">
  <origin
    xyz="0 -0.5 0"
    rpy="0 0 0" />
  <parent
    link="base_link" />
  <child
    link="arm_1_link_base" />
  <axis
    xyz="0 0 1" />
  <limit
    lower="-3.1415926"
    upper="3.1415926"
    effort="250"
    velocity="180.0" />
</joint>

  <link
    name="arm_1_link_1">
    <inertial>
      <origin
        xyz="0.000021 0.004967 -0.01790"
        rpy="0 0 0" />
      <mass
        value="4.657" />
      <inertia
        ixx="1.0752E-05"
        ixy="7.523E-09"
        ixz="1.0743E-08"
        iyy="1.0133197E-05"
        iyz="4.49349E-07"
        izz="7.870754E-05" />
    </inertial>
    <visual>
      <origin
        xyz="0 0 0"
        rpy="0 0 0" />
      <geometry>
        <mesh
          filename="package://duco_support/meshes/dual_gcr5/link_1.stl" />
      </geometry>
      <material
        name="">
        <color
          rgba="0.79216 0.81961 0.93333 1" />
      </material>
    </visual>
    <collision>
      <origin
        xyz="0 0 0"
        rpy="0 0 0" />
      <geometry>
        <mesh
          filename="package://duco_support/meshes/dual_gcr5/link_1.stl" />
      </geometry>
    </collision>
  </link>
  <joint
    name="arm_1_joint_1"
    type="revolute">
    <origin
      xyz="0 0 0.122"
      rpy="0 0 0" />
    <parent
      link="arm_1_link_base" />
    <child
      link="arm_1_link_1" />
    <axis
      xyz="0 0 1" />
    <limit
      lower="-3.1415926"
      upper="3.1415926"
      effort="250"
      velocity="180.0" />
  </joint>
  <link
    name="arm_1_link_2">
    <inertial>
      <origin
        xyz="0.21612 -1.8576E-16 0.014189"
        rpy="0 0 0" />
      <mass
        value="3.3497" />
      <inertia
        ixx="0.0069086"
        ixy="8.2574E-08"
        ixz="9.7307E-18"
        iyy="0.022883"
        iyz="2.8358E-18"
        izz="0.024046" />
    </inertial>
    <visual>
      <origin
        xyz="0 0 0"
        rpy="0 0 0" />
      <geometry>
        <mesh
          filename="package://duco_support/meshes/dual_gcr5/link_2.stl" />
      </geometry>
      <material
        name="">
        <color
          rgba="0.79216 0.81961 0.93333 1" />
      </material>
    </visual>
    <collision>
      <origin
        xyz="0 0 0"
        rpy="0 0 0" />
      <geometry>
        <mesh
          filename="package://duco_support/meshes/dual_gcr5/link_2.stl" />
      </geometry>
    </collision>
  </link>
  <joint
    name="arm_1_joint_2"
    type="revolute">
    <origin
      xyz="0 0.1405 0"
      rpy="1.5708 -1.5708 3.1416" />
    <parent
      link="arm_1_link_1" />
    <child
      link="arm_1_link_2" />
    <axis
      xyz="0 0 1" />
    <limit
      lower="-3.1415926"
      upper="3.1415926"
      effort="250"
      velocity="180.0" />
  </joint>
  <link
    name="arm_1_link_3">
    <inertial>
      <origin
        xyz="0.10177 2.95E-08 -0.11478"
        rpy="0 0 0" />
      <mass
        value="2.9857" />
      <inertia
        ixx="0.0035253"
        ixy="-2.5122E-08"
        ixz="0.00038746"
        iyy="0.010268"
        iyz="2.8848E-09"
        izz="0.010609" />
    </inertial>
    <visual>
      <origin
        xyz="0 0 0"
        rpy="0 0 0" />
      <geometry>
        <mesh
          filename="package://duco_support/meshes/dual_gcr5/link_3.stl" />
      </geometry>
      <material
        name="">
        <color
          rgba="0.79216 0.81961 0.93333 1" />
      </material>
    </visual>
    <collision>
      <origin
        xyz="0 0 0"
        rpy="0 0 0" />
      <geometry>
        <mesh
          filename="package://duco_support/meshes/dual_gcr5/link_3.stl" />
      </geometry>
    </collision>
  </link>
  <joint
    name="arm_1_joint_3"
    type="revolute">
    <origin
      xyz="0.425 0 0"
      rpy="0 0 0" />
    <parent
      link="arm_1_link_2" />
    <child
      link="arm_1_link_3" />
    <axis
      xyz="0 0 1" />
    <limit
      lower="-3.1415926"
      upper="3.1415926"
      effort="150"
      velocity="225.0" />
  </joint>
  <link
    name="arm_1_link_4">
    <inertial>
      <origin
        xyz="-7.7387E-07 0.0063161 -0.0061589"
        rpy="0 0 0" />
      <mass
        value="0.37228" />
      <inertia
        ixx="0.00048225"
        ixy="5.8826E-09"
        ixz="2.1987E-08"
        iyy="0.00055656"
        iyz="5.1696E-05"
        izz="0.00041144" />
    </inertial>
    <visual>
      <origin
        xyz="0 0 0"
        rpy="0 0 0" />
      <geometry>
        <mesh
          filename="package://duco_support/meshes/dual_gcr5/link_4.stl" />
      </geometry>
      <material
        name="">
        <color
          rgba="0.73333 0.78039 0.83922 1" />
      </material>
    </visual>
    <collision>
      <origin
        xyz="0 0 0"
        rpy="0 0 0" />
      <geometry>
        <mesh
          filename="package://duco_support/meshes/dual_gcr5/link_4.stl" />
      </geometry>
    </collision>
  </link>
  <joint
    name="arm_1_joint_4"
    type="revolute">
    <origin
      xyz="0.392 0 0"
      rpy="0 0 1.5708" />
    <parent
      link="arm_1_link_3" />
    <child
      link="arm_1_link_4" />
    <axis
      xyz="0 0 1" />
    <limit
      lower="-3.1415926"
      upper="3.1415926"
      effort="50"
      velocity="225.0" />
  </joint>
  <link
    name="arm_1_link_5">
    <inertial>
      <origin
        xyz="7.731E-07 -0.008004 0.00087192"
        rpy="0 0 0" />
      <mass
        value="0.32906" />
      <inertia
        ixx="0.00034489"
        ixy="2.4698E-09"
        ixz="-2.3229E-08"
        iyy="0.00042119"
        iyz="-3.743E-05"
        izz="0.00034777" />
    </inertial>
    <visual>
      <origin
        xyz="0 0 0"
        rpy="0 0 0" />
      <geometry>
        <mesh
          filename="package://duco_support/meshes/dual_gcr5/link_5.stl" />
      </geometry>
      <material
        name="">
        <color
          rgba="0.73333 0.78039 0.83922 1" />
      </material>
    </visual>
    <collision>
      <origin
        xyz="0 0 0"
        rpy="0 0 0" />
      <geometry>
        <mesh
          filename="package://duco_support/meshes/dual_gcr5/link_5.stl" />
      </geometry>
    </collision>
  </link>
  <joint
    name="arm_1_joint_5"
    type="revolute">
    <origin
      xyz="0 -0.1 0"
      rpy="1.5708 0 0" />
    <parent
      link="arm_1_link_4" />
    <child
      link="arm_1_link_5" />
    <axis
      xyz="0 0 1" />
    <limit
      lower="-3.1415926"
      upper="3.1415926"
      effort="50"
      velocity="225.0" />
  </joint>
  <link
    name="arm_1_link_6">
    <inertial>
      <origin
        xyz="-2.7264E-05 -0.0031969 -0.013722"
        rpy="0 0 0" />
      <mass
        value="0.19147" />
      <inertia
        ixx="0.00010193"
        ixy="-1.7257E-10"
        ixz="9.7552E-19"
        iyy="0.00010193"
        iyz="-7.9276E-20"
        izz="0.00018851" />
    </inertial>
    <visual>
      <origin
        xyz="0 0 0"
        rpy="0 0 0" />
      <geometry>
        <mesh
          filename="package://duco_support/meshes/dual_gcr5/link_6.stl" />
      </geometry>
      <material
        name="">
        <color
          rgba="0 0 0 1" />
      </material>
    </visual>
    <collision>
      <origin
        xyz="0 0 0"
        rpy="0 0 0" />
      <geometry>
        <mesh
          filename="package://duco_support/meshes/dual_gcr5/link_6.stl" />
      </geometry>
    </collision>
  </link>
  <joint
    name="arm_1_joint_6"
    type="revolute">
    <origin
      xyz="0 0.105 0"
      rpy="-1.5708 0 0" />
    <parent
      link="arm_1_link_5" />
    <child
      link="arm_1_link_6" />
    <axis
      xyz="0 0 1" />
    <limit
      lower="-3.1415926"
      upper="3.1415926"
      effort="50"
      velocity="225.0" />
  </joint>
<link name="end_1"/>
<joint
    name="end_1_joint"
    type="fixed">
    <parent
      link="arm_1_link_6" />
    <child
      link="end_1" />
</joint>



<link
  name="arm_2_link_base">
  <inertial>
    <origin
      xyz="0.000021 0.004967 -0.01790"
      rpy="0 0 0" />
    <mass
      value="4.657" />
    <inertia
      ixx="1.0752E-05"
      ixy="7.523E-09"
      ixz="1.0743E-08"
      iyy="1.0133197E-05"
      iyz="4.49349E-07"
      izz="7.870754E-05" />
  </inertial>
  <visual>
    <origin
      xyz="0 0 0"
      rpy="0 0 0" />
    <geometry>
      <mesh
        filename="package://duco_support/meshes/dual_gcr5/base_link.stl" />
    </geometry>
    <material
      name="">
      <color
        rgba="0.79216 0.81961 0.93333 1" />
    </material>
  </visual>
  <collision>
    <origin
      xyz="0 0 0"
      rpy="0 0 0" />
    <geometry>
      <mesh
        filename="package://duco_support/meshes/dual_gcr5/base_link.stl" />
    </geometry>
  </collision>
</link>
<joint
  name="arm_2_joint_base"
  type="fixed">
  <origin
    xyz="0 0.5 0"
    rpy="0 0 0" />
  <parent
    link="base_link" />
  <child
    link="arm_2_link_base" />
  <axis
    xyz="0 0 1" />
  <limit
    lower="-3.1415926"
    upper="3.1415926"
    effort="250"
    velocity="180.0" />
</joint>

  <link
    name="arm_2_link_1">
    <inertial>
      <origin
        xyz="0.000021 0.004967 -0.01790"
        rpy="0 0 0" />
      <mass
        value="4.657" />
      <inertia
        ixx="1.0752E-05"
        ixy="7.523E-09"
        ixz="1.0743E-08"
        iyy="1.0133197E-05"
        iyz="4.49349E-07"
        izz="7.870754E-05" />
    </inertial>
    <visual>
      <origin
        xyz="0 0 0"
        rpy="0 0 0" />
      <geometry>
        <mesh
          filename="package://duco_support/meshes/dual_gcr5/link_1.stl" />
      </geometry>
      <material
        name="">
        <color
          rgba="0.79216 0.81961 0.93333 1" />
      </material>
    </visual>
    <collision>
      <origin
        xyz="0 0 0"
        rpy="0 0 0" />
      <geometry>
        <mesh
          filename="package://duco_support/meshes/dual_gcr5/link_1.stl" />
      </geometry>
    </collision>
  </link>
  <joint
    name="arm_2_joint_1"
    type="revolute">
    <origin
      xyz="0 0 0.122"
      rpy="0 0 0" />
    <parent
      link="arm_2_link_base" />
    <child
      link="arm_2_link_1" />
    <axis
      xyz="0 0 1" />
    <limit
      lower="-3.1415926"
      upper="3.1415926"
      effort="250"
      velocity="180.0" />
  </joint>
  <link
    name="arm_2_link_2">
    <inertial>
      <origin
        xyz="0.21612 -1.8576E-16 0.014189"
        rpy="0 0 0" />
      <mass
        value="3.3497" />
      <inertia
        ixx="0.0069086"
        ixy="8.2574E-08"
        ixz="9.7307E-18"
        iyy="0.022883"
        iyz="2.8358E-18"
        izz="0.024046" />
    </inertial>
    <visual>
      <origin
        xyz="0 0 0"
        rpy="0 0 0" />
      <geometry>
        <mesh
          filename="package://duco_support/meshes/dual_gcr5/link_2.stl" />
      </geometry>
      <material
        name="">
        <color
          rgba="0.79216 0.81961 0.93333 1" />
      </material>
    </visual>
    <collision>
      <origin
        xyz="0 0 0"
        rpy="0 0 0" />
      <geometry>
        <mesh
          filename="package://duco_support/meshes/dual_gcr5/link_2.stl" />
      </geometry>
    </collision>
  </link>
  <joint
    name="arm_2_joint_2"
    type="revolute">
    <origin
      xyz="0 0.1405 0"
      rpy="1.5708 -1.5708 3.1416" />
    <parent
      link="arm_2_link_1" />
    <child
      link="arm_2_link_2" />
    <axis
      xyz="0 0 1" />
    <limit
      lower="-3.1415926"
      upper="3.1415926"
      effort="250"
      velocity="180.0" />
  </joint>
  <link
    name="arm_2_link_3">
    <inertial>
      <origin
        xyz="0.10177 2.95E-08 -0.11478"
        rpy="0 0 0" />
      <mass
        value="2.9857" />
      <inertia
        ixx="0.0035253"
        ixy="-2.5122E-08"
        ixz="0.00038746"
        iyy="0.010268"
        iyz="2.8848E-09"
        izz="0.010609" />
    </inertial>
    <visual>
      <origin
        xyz="0 0 0"
        rpy="0 0 0" />
      <geometry>
        <mesh
          filename="package://duco_support/meshes/dual_gcr5/link_3.stl" />
      </geometry>
      <material
        name="">
        <color
          rgba="0.79216 0.81961 0.93333 1" />
      </material>
    </visual>
    <collision>
      <origin
        xyz="0 0 0"
        rpy="0 0 0" />
      <geometry>
        <mesh
          filename="package://duco_support/meshes/dual_gcr5/link_3.stl" />
      </geometry>
    </collision>
  </link>
  <joint
    name="arm_2_joint_3"
    type="revolute">
    <origin
      xyz="0.425 0 0"
      rpy="0 0 0" />
    <parent
      link="arm_2_link_2" />
    <child
      link="arm_2_link_3" />
    <axis
      xyz="0 0 1" />
    <limit
      lower="-3.1415926"
      upper="3.1415926"
      effort="150"
      velocity="225.0" />
  </joint>
  <link
    name="arm_2_link_4">
    <inertial>
      <origin
        xyz="-7.7387E-07 0.0063161 -0.0061589"
        rpy="0 0 0" />
      <mass
        value="0.37228" />
      <inertia
        ixx="0.00048225"
        ixy="5.8826E-09"
        ixz="2.1987E-08"
        iyy="0.00055656"
        iyz="5.1696E-05"
        izz="0.00041144" />
    </inertial>
    <visual>
      <origin
        xyz="0 0 0"
        rpy="0 0 0" />
      <geometry>
        <mesh
          filename="package://duco_support/meshes/dual_gcr5/link_4.stl" />
      </geometry>
      <material
        name="">
        <color
          rgba="0.73333 0.78039 0.83922 1" />
      </material>
    </visual>
    <collision>
      <origin
        xyz="0 0 0"
        rpy="0 0 0" />
      <geometry>
        <mesh
          filename="package://duco_support/meshes/dual_gcr5/link_4.stl" />
      </geometry>
    </collision>
  </link>
  <joint
    name="arm_2_joint_4"
    type="revolute">
    <origin
      xyz="0.392 0 0"
      rpy="0 0 1.5708" />
    <parent
      link="arm_2_link_3" />
    <child
      link="arm_2_link_4" />
    <axis
      xyz="0 0 1" />
    <limit
      lower="-3.1415926"
      upper="3.1415926"
      effort="50"
      velocity="225.0" />
  </joint>
  <link
    name="arm_2_link_5">
    <inertial>
      <origin
        xyz="7.731E-07 -0.008004 0.00087192"
        rpy="0 0 0" />
      <mass
        value="0.32906" />
      <inertia
        ixx="0.00034489"
        ixy="2.4698E-09"
        ixz="-2.3229E-08"
        iyy="0.00042119"
        iyz="-3.743E-05"
        izz="0.00034777" />
    </inertial>
    <visual>
      <origin
        xyz="0 0 0"
        rpy="0 0 0" />
      <geometry>
        <mesh
          filename="package://duco_support/meshes/dual_gcr5/link_5.stl" />
      </geometry>
      <material
        name="">
        <color
          rgba="0.73333 0.78039 0.83922 1" />
      </material>
    </visual>
    <collision>
      <origin
        xyz="0 0 0"
        rpy="0 0 0" />
      <geometry>
        <mesh
          filename="package://duco_support/meshes/dual_gcr5/link_5.stl" />
      </geometry>
    </collision>
  </link>
  <joint
    name="arm_2_joint_5"
    type="revolute">
    <origin
      xyz="0 -0.1 0"
      rpy="1.5708 0 0" />
    <parent
      link="arm_2_link_4" />
    <child
      link="arm_2_link_5" />
    <axis
      xyz="0 0 1" />
    <limit
      lower="-3.1415926"
      upper="3.1415926"
      effort="50"
      velocity="225.0" />
  </joint>
  <link
    name="arm_2_link_6">
    <inertial>
      <origin
        xyz="-2.7264E-05 -0.0031969 -0.013722"
        rpy="0 0 0" />
      <mass
        value="0.19147" />
      <inertia
        ixx="0.00010193"
        ixy="-1.7257E-10"
        ixz="9.7552E-19"
        iyy="0.00010193"
        iyz="-7.9276E-20"
        izz="0.00018851" />
    </inertial>
    <visual>
      <origin
        xyz="0 0 0"
        rpy="0 0 0" />
      <geometry>
        <mesh
          filename="package://duco_support/meshes/dual_gcr5/link_6.stl" />
      </geometry>
      <material
        name="">
        <color
          rgba="0 0 0 1" />
      </material>
    </visual>
    <collision>
      <origin
        xyz="0 0 0"
        rpy="0 0 0" />
      <geometry>
        <mesh
          filename="package://duco_support/meshes/dual_gcr5/link_6.stl" />
      </geometry>
    </collision>
  </link>
  <joint
    name="arm_2_joint_6"
    type="revolute">
    <origin
      xyz="0 0.105 0"
      rpy="-1.5708 0 0" />
    <parent
      link="arm_2_link_5" />
    <child
      link="arm_2_link_6" />
    <axis
      xyz="0 0 1" />
    <limit
      lower="-3.1415926"
      upper="3.1415926"
      effort="50"
      velocity="225.0" />
  </joint>
<link name="end_2"/>
<joint
    name="end_2_joint"
    type="fixed">
    <parent
      link="arm_2_link_6" />
    <child
      link="end_2" />
</joint>
</robot>
