<?xml version="1.0" encoding="utf-8"?>
<!-- This URDF was automatically created by SolidWorks to URDF Exporter! Originally created by Stephen Brawner (brawner@gmail.com) 
     Commit Version: 1.6.0-4-g7f85cfe  Build Version: 1.6.7995.38578
     For more information, please see http://wiki.ros.org/sw_urdf_exporter -->
<robot
  name="gcr30_1100">
  <link
    name="base_link">
    <inertial>
      <origin
        xyz="1.0276E-05 0.014119 0.064841"
        rpy="0 0 0" />
      <mass
        value="2.128" />
      <inertia
        ixx="0.013624"
        ixy="-1.2075E-05"
        ixz="1.8225E-06"
        iyy="0.018307"
        iyz="0.00049878"
        izz="0.023934" />
    </inertial>
    <visual>
      <origin
        xyz="0 0 0"
        rpy="0 0 0" />
      <geometry>
        <mesh
          filename="package://duco_support/meshes/GCR30_1100/base_link.stl" />
      </geometry>
      <material
        name="">
        <color
          rgba="0.79216 0.81961 0.93333 1" />
      </material>
    </visual>
    <collision>
      <origin
        xyz="0 0 0"
        rpy="0 0 0" />
      <geometry>
        <mesh
          filename="package://duco_support/meshes/GCR30_1100/base_link.stl" />
      </geometry>
    </collision>
  </link>
  <link
    name="link_1">
    <inertial>
      <origin
        xyz="1.0951E-07 0.021145 0.0017549"
        rpy="0 0 0" />
      <mass
        value="14.725" />
      <inertia
        ixx="0.066928"
        ixy="3.4809E-07"
        ixz="2.7188E-07"
        iyy="0.06743"
        iyz="-0.0064955"
        izz="0.071272" />
    </inertial>
    <visual>
      <origin
        xyz="0 0 0"
        rpy="0 0 0" />
      <geometry>
        <mesh
          filename="package://duco_support/meshes/GCR30_1100/link_1.stl" />
      </geometry>
      <material
        name="">
        <color
          rgba="0.73333 0.78039 0.83922 1" />
      </material>
    </visual>
    <collision>
      <origin
        xyz="0 0 0"
        rpy="0 0 0" />
      <geometry>
        <mesh
          filename="package://duco_support/meshes/GCR30_1100/link_1.stl" />
      </geometry>
    </collision>
  </link>
  <joint
    name="arm_1_joint_1"
    type="revolute">
    <origin
      xyz="0 0 0.235"
      rpy="0 0 0" />
    <parent
      link="base_link" />
    <child
      link="link_1" />
    <axis
      xyz="0 0 1" />
    <limit
      lower="-3.1415926"
      upper="3.1415926"
      effort="850"
      velocity="2.094395102" />
  </joint>
  <link
    name="link_2">
    <inertial>
      <origin
        xyz="0.19999 -7.3565E-07 0.037425"
        rpy="0 0 0" />
      <mass
        value="25.912" />
      <inertia
        ixx="0.11326"
        ixy="-9.4175E-07"
        ixz="-0.0039858"
        iyy="0.16267"
        iyz="1.1586E-06"
        izz="0.16558" />
    </inertial>
    <visual>
      <origin
        xyz="0 0 0"
        rpy="0 0 0" />
      <geometry>
        <mesh
          filename="package://duco_support/meshes/GCR30_1100/link_2.stl" />
      </geometry>
      <material
        name="">
        <color
          rgba="0.79216 0.81961 0.93333 1" />
      </material>
    </visual>
    <collision>
      <origin
        xyz="0 0 0"
        rpy="0 0 0" />
      <geometry>
        <mesh
          filename="package://duco_support/meshes/GCR30_1100/link_2.stl" />
      </geometry>
    </collision>
  </link>
  <joint
    name="arm_1_joint_2"
    type="revolute">
    <origin
      xyz="0 0.1793 0"
      rpy="1.5708 -1.5708 3.1416" />
    <parent
      link="link_1" />
    <child
      link="link_2" />
    <axis
      xyz="0 0 1" />
    <limit
      lower="-3.1415926"
      upper="3.1415926"
      effort="850"
      velocity="2.094395102" />
  </joint>
  <link
    name="link_3">
    <inertial>
      <origin
        xyz="0.20158 -1.857E-07 -0.13238"
        rpy="0 0 0" />
      <mass
        value="7.595" />
      <inertia
        ixx="0.029966"
        ixy="1.4877E-07"
        ixz="0.0014216"
        iyy="0.076218"
        iyz="-3.8408E-08"
        izz="0.076757" />
    </inertial>
    <visual>
      <origin
        xyz="0 0 0"
        rpy="0 0 0" />
      <geometry>
        <mesh
          filename="package://duco_support/meshes/GCR30_1100/link_3.stl" />
      </geometry>
      <material
        name="">
        <color
          rgba="0.79216 0.81961 0.93333 1" />
      </material>
    </visual>
    <collision>
      <origin
        xyz="0 0 0"
        rpy="0 0 0" />
      <geometry>
        <mesh
          filename="package://duco_support/meshes/GCR30_1100/link_3.stl" />
      </geometry>
    </collision>
  </link>
  <joint
    name="arm_1_joint_3"
    type="revolute">
    <origin
      xyz="0.496 0 0"
      rpy="0 0 0" />
    <parent
      link="link_2" />
    <child
      link="link_3" />
    <axis
      xyz="0 0 1" />
    <limit
      lower="-3.1415926"
      upper="3.1415926"
      effort="440"
      velocity="3.1415926" />
  </joint>
  <link
    name="link_4">
    <inertial>
      <origin
        xyz="-8.671E-07 -0.0017736 -0.014039"
        rpy="0 0 0" />
      <mass
        value="4.705" />
      <inertia
        ixx="0.008699"
        ixy="-6.6695E-08"
        ixz="1.574E-08"
        iyy="0.0082917"
        iyz="0.00074702"
        izz="0.0086035" />
    </inertial>
    <visual>
      <origin
        xyz="0 0 0"
        rpy="0 0 0" />
      <geometry>
        <mesh
          filename="package://duco_support/meshes/GCR30_1100/link_4.stl" />
      </geometry>
      <material
        name="">
        <color
          rgba="0.79216 0.81961 0.93333 1" />
      </material>
    </visual>
    <collision>
      <origin
        xyz="0 0 0"
        rpy="0 0 0" />
      <geometry>
        <mesh
          filename="package://duco_support/meshes/GCR30_1100/link_4.stl" />
      </geometry>
    </collision>
  </link>
  <joint
    name="arm_1_joint_4"
    type="revolute">
    <origin
      xyz="0.4595 0 0"
      rpy="0 0 1.5708" />
    <parent
      link="link_3" />
    <child
      link="link_4" />
    <axis
      xyz="0 0 1" />
    <limit
      lower="-3.1415926"
      upper="3.1415926"
      effort="205"
      velocity="3.926990817" />
  </joint>
  <link
    name="link_5">
    <inertial>
      <origin
        xyz="-2.7502E-07 0.0017736 -0.014039"
        rpy="0 0 0" />
      <mass
        value="4.705" />
      <inertia
        ixx="0.008699"
        ixy="1.3768E-07"
        ixz="-1.0778E-07"
        iyy="0.0082917"
        iyz="-0.00074702"
        izz="0.0086035" />
    </inertial>
    <visual>
      <origin
        xyz="0 0 0"
        rpy="0 0 0" />
      <geometry>
        <mesh
          filename="package://duco_support/meshes/GCR30_1100/link_5.stl" />
      </geometry>
      <material
        name="">
        <color
          rgba="0.79216 0.81961 0.93333 1" />
      </material>
    </visual>
    <collision>
      <origin
        xyz="0 0 0"
        rpy="0 0 0" />
      <geometry>
        <mesh
          filename="package://duco_support/meshes/GCR30_1100/link_5.stl" />
      </geometry>
    </collision>
  </link>
  <joint
    name="arm_1_joint_5"
    type="revolute">
    <origin
      xyz="0 -0.1445 0"
      rpy="1.5708 0 0" />
    <parent
      link="link_4" />
    <child
      link="link_5" />
    <axis
      xyz="0 0 1" />
    <limit
      lower="-3.1415926"
      upper="3.1415926"
      effort="205"
      velocity="3.926990817" />
  </joint>
  <link
    name="link_6">
    <inertial>
      <origin
        xyz="2.5622E-07 0.00026203 -0.032568"
        rpy="0 0 0" />
      <mass
        value="1.652" />
      <inertia
        ixx="0.0010085"
        ixy="2.8568E-19"
        ixz="-1.2409E-18"
        iyy="0.0010085"
        iyz="-1.2499E-18"
        izz="0.0018936" />
    </inertial>
    <visual>
      <origin
        xyz="0 0 0"
        rpy="0 0 0" />
      <geometry>
        <mesh
          filename="package://duco_support/meshes/GCR30_1100/link_6.stl" />
      </geometry>
      <material
        name="">
        <color
          rgba="0.86667 0.86667 0.8902 1" />
      </material>
    </visual>
    <collision>
      <origin
        xyz="0 0 0"
        rpy="0 0 0" />
      <geometry>
        <mesh
          filename="package://duco_support/meshes/GCR30_1100/link_6.stl" />
      </geometry>
    </collision>
  </link>
  <joint
    name="arm_1_joint_6"
    type="revolute">
    <origin
      xyz="0 0.121 0"
      rpy="-1.5708 0 0" />
    <parent
      link="link_5" />
    <child
      link="link_6" />
    <axis
      xyz="0 0 1" />
    <limit
      lower="-3.1415926"
      upper="3.1415926"
      effort="205"
      velocity="3.926990817" />
  </joint>
</robot>
