<?xml version="1.0" encoding="utf-8"?>
<!-- This URDF was automatically created by SolidWorks to URDF Exporter! Originally created by Stephen Brawner (brawner@gmail.com) 
     Commit Version: 1.6.0-4-g7f85cfe  Build Version: 1.6.7995.38578
     For more information, please see http://wiki.ros.org/sw_urdf_exporter -->
<robot
  name="gcr10_2000">
  <link
    name="base_link">
    <inertial>
      <origin
        xyz="1.0276E-05 0.014119 0.064841"
        rpy="0 0 0" />
      <mass
        value="0" />
      <inertia
        ixx="0.0"
        ixy="0.0"
        ixz="0.0"
        iyy="0.0"
        iyz="0.0"
        izz="0.0" />
    </inertial>
    <visual>
      <origin
        xyz="0 0 0"
        rpy="0 0 0" />
      <geometry>
        <mesh
          filename="package://duco_support/meshes/GCR10_2000/base_link.stl" />
      </geometry>
      <material
        name="">
        <color
          rgba="0.73333 0.78039 0.83922 1" />
      </material>
    </visual>
    <collision>
      <origin
        xyz="0 0 0"
        rpy="0 0 0" />
      <geometry>
        <mesh
          filename="package://duco_support/meshes/GCR10_2000/base_link.stl" />
      </geometry>
    </collision>
  </link>
  <link
    name="link_1">
    <inertial>
      <origin
        xyz="0.000021 0.004967 -0.01790"
        rpy="0 0 0" />
      <mass
        value="4.657" />
      <inertia
        ixx="1.0752E-05"
        ixy="7.523E-09"
        ixz="1.0743E-08"
        iyy="1.0133197E-05"
        iyz="4.49349E-07"
        izz="7.870754E-05" />
    </inertial>
    <visual>
      <origin
        xyz="0 0 0"
        rpy="0 0 0" />
      <geometry>
        <mesh
          filename="package://duco_support/meshes/GCR10_2000/link_1.stl" />
      </geometry>
      <material
        name="">
        <color
          rgba="0.79216 0.81961 0.93333 1" />
      </material>
    </visual>
    <collision>
      <origin
        xyz="0 0 0"
        rpy="0 0 0" />
      <geometry>
        <mesh
          filename="package://duco_support/meshes/GCR10_2000/link_1.stl" />
      </geometry>
    </collision>
  </link>
  <joint
    name="arm_1_joint_1"
    type="revolute">
    <origin
      xyz="0 0 0.235"
      rpy="0 0 0" />
    <parent
      link="base_link" />
    <child
      link="link_1" />
    <axis
      xyz="0 0 1" />
    <limit
      lower="-3.1415926"
      upper="3.1415926"
      effort="850"
      velocity="2.094395102" />
  </joint>

  <link
    name="link_2">
    <inertial>
      <origin
        xyz="1.102E-07 0.020908 0.00079543"
        rpy="0 0 0" />
      <mass
        value="12.162" />
      <inertia
        ixx="0.067005"
        ixy="3.4805E-07"
        ixz="2.7185E-07"
        iyy="0.067506"
        iyz="-0.0064954"
        izz="0.071423" />
    </inertial>
    <visual>
      <origin
        xyz="0 0 0"
        rpy="0 0 0" />
      <geometry>
        <mesh
          filename="package://duco_support/meshes/GCR10_2000/link_2.stl" />
      </geometry>
      <material
        name="">
        <color
          rgba="0.79216 0.81961 0.93333 1" />
      </material>
    </visual>
    <collision>
      <origin
        xyz="0 0 0"
        rpy="0 0 0" />
      <geometry>
        <mesh
          filename="package://duco_support/meshes/GCR10_2000/link_2.stl" />
      </geometry>
    </collision>
  </link>
  <joint
    name="arm_1_joint_2"
    type="revolute">
    <origin
      xyz="0 0.1608 0"
      rpy="1.5708 -1.5708 3.1416" />
    <parent
      link="link_1" />
    <child
      link="link_2" />
    <axis
      xyz="0 0 1" />
    <limit
      lower="-3.1415926"
      upper="3.1415926"
      effort="850"
      velocity="2.094395102" />
  </joint>
  <link
    name="link_3">
    <inertial>
      <origin
        xyz="0.31434 -1.0432E-06 -0.11596"
        rpy="0 0 0" />
      <mass
        value="6.787" />
      <inertia
        ixx="0.029837"
        ixy="6.3415E-06"
        ixz="-0.00036881"
        iyy="0.71686"
        iyz="-4.683E-07"
        izz="0.71691" />
    </inertial>
    <visual>
      <origin
        xyz="0 0 0"
        rpy="0 0 0" />
      <geometry>
        <mesh
          filename="package://duco_support/meshes/GCR10_2000/link_3.stl" />
      </geometry>
      <material
        name="">
        <color
          rgba="0.86667 0.86667 0.8902 1" />
      </material>
    </visual>
    <collision>
      <origin
        xyz="0 0 0"
        rpy="0 0 0" />
      <geometry>
        <mesh
          filename="package://duco_support/meshes/GCR10_2000/link_3.stl" />
      </geometry>
    </collision>
  </link>
  <joint
    name="arm_1_joint_3"
    type="revolute">
    <origin
      xyz="0.9775 0 0"
      rpy="0 0 0" />
    <parent
      link="link_2" />
    <child
      link="link_3" />
    <axis
      xyz="0 0 1" />
    <limit
      lower="-3.1415926"
      upper="3.1415926"
      effort="440"
      velocity="3.1415926535" />
  </joint>
  <link
    name="link_4">
    <inertial>
      <origin
        xyz="1.2372E-05 -0.014753 -0.0001724"
        rpy="0 0 0" />
      <mass
        value="2.453" />
      <inertia
        ixx="0.001367"
        ixy="-1.1419E-07"
        ixz="-2.6082E-08"
        iyy="0.00054941"
        iyz="-2.3461E-05"
        izz="0.0013257" />
    </inertial>
    <visual>
      <origin
        xyz="0 0 0"
        rpy="0 0 0" />
      <geometry>
        <mesh
          filename="package://duco_support/meshes/GCR10_2000/link_4.stl" />
      </geometry>
      <material
        name="">
        <color
          rgba="0.86667 0.86667 0.8902 1" />
      </material>
    </visual>
    <collision>
      <origin
        xyz="0 0 0"
        rpy="0 0 0" />
      <geometry>
        <mesh
          filename="package://duco_support/meshes/GCR10_2000/link_4.stl" />
      </geometry>
    </collision>
  </link>
  <joint
    name="arm_1_joint_4"
    type="revolute">
    <origin
      xyz="0.8965 0 0"
      rpy="0 0 1.5708" />
    <parent
      link="link_3" />
    <child
      link="link_4" />
    <axis
      xyz="0 0 1" />
    <limit
      lower="-3.1415926"
      upper="3.1415926"
      effort="75"
      velocity="3.926990817" />
  </joint>
  <link
    name="link_5">
    <inertial>
      <origin
        xyz="-1.2211E-05 0.014754 -0.00017351"
        rpy="0 0 0" />
      <mass
        value="2.453" />
      <inertia
        ixx="0.001367"
        ixy="-1.1551E-07"
        ixz="2.5518E-08"
        iyy="0.00054941"
        iyz="2.3461E-05"
        izz="0.0013257" />
    </inertial>
    <visual>
      <origin
        xyz="0 0 0"
        rpy="0 0 0" />
      <geometry>
        <mesh
          filename="package://duco_support/meshes/GCR10_2000/link_5.stl" />
      </geometry>
      <material
        name="">
        <color
          rgba="0.86667 0.86667 0.8902 1" />
      </material>
    </visual>
    <collision>
      <origin
        xyz="0 0 0"
        rpy="0 0 0" />
      <geometry>
        <mesh
          filename="package://duco_support/meshes/GCR10_2000/link_5.stl" />
      </geometry>
    </collision>
  </link>
  <joint
    name="arm_1_joint_5"
    type="revolute">
    <origin
      xyz="0 -0.126 0"
      rpy="1.5708 0 0" />
    <parent
      link="link_4" />
    <child
      link="link_5" />
    <axis
      xyz="0 0 1" />
    <limit
      lower="-3.1415926"
      upper="3.1415926"
      effort="75"
      velocity="3.926990817" />
  </joint>
  <link
    name="link_6">
    <inertial>
      <origin
        xyz="-5.2419E-07 0.00029705 -0.025541"
        rpy="0 0 0" />
      <mass
        value="2.453" />
      <inertia
        ixx="3.517E-05"
        ixy="7.061E-10"
        ixz="7.5214E-11"
        iyy="3.4071E-05"
        iyz="-5.7792E-08"
        izz="6.3885E-05" />
    </inertial>
    <visual>
      <origin
        xyz="0 0 0"
        rpy="0 0 0" />
      <geometry>
        <mesh
          filename="package://duco_support/meshes/GCR10_2000/link_6.stl" />
      </geometry>
      <material
        name="">
        <color
          rgba="0 0 0 1" />
      </material>
    </visual>
    <collision>
      <origin
        xyz="0 0 0"
        rpy="0 0 0" />
      <geometry>
        <mesh
          filename="package://duco_support/meshes/GCR10_2000/link_6.stl" />
      </geometry>
    </collision>
  </link>
  <joint
    name="arm_1_joint_6"
    type="revolute">
    <origin
      xyz="0 0.113 0"
      rpy="-1.5708 0 0" />
    <parent
      link="link_5" />
    <child
      link="link_6" />
    <axis
      xyz="0 0 1" />
    <limit
      lower="-3.1415926"
      upper="3.1415926"
      effort="75"
      velocity="3.926990817" />
  </joint>
</robot>
