<?xml version="1.0" encoding="utf-8"?>
<!-- This URDF was automatically created by SolidWorks to URDF Exporter! Originally created by Stephen Brawner (brawner@gmail.com) 
     Commit Version: 1.6.0-4-g7f85cfe  Build Version: 1.6.7995.38578
     For more information, please see http://wiki.ros.org/sw_urdf_exporter -->
<robot
  name="duco_gcr5_910_urdf">
  <link
    name="base_link">
    <inertial>
      <origin
        xyz="-0.00404865240257839 0.0198244231719463 -2.12214937475772E-05"
        rpy="0 0 0" />
      <mass
        value="0.729857387154036" />
      <inertia
        ixx="0.0013739098152086"
        ixy="-2.29528040086667E-05"
        ixz="4.44203950037754E-06"
        iyy="0.00232503532405019"
        iyz="-2.05595022856958E-07"
        izz="0.00115595774024397" />
    </inertial>
    <visual>
      <origin
        xyz="0 0 0"
        rpy="0 0 0" />
      <geometry>
        <mesh
          filename="package://duco_gcr5_910_urdf/meshes/base_link.STL" />
      </geometry>
      <material
        name="">
        <color
          rgba="0.792156862745098 0.819607843137255 0.933333333333333 1" />
      </material>
    </visual>
    <collision>
      <origin
        xyz="0 0 0"
        rpy="0 0 0" />
      <geometry>
        <mesh
          filename="package://duco_gcr5_910_urdf/meshes/base_link.STL" />
      </geometry>
    </collision>
  </link>
  <link
    name="link1">
    <inertial>
      <origin
        xyz="0.118567570760599 0.0138158311105798 7.82313711048054E-07"
        rpy="0 0 0" />
      <mass
        value="0.424385093655344" />
      <inertia
        ixx="0.00100544458550602"
        ixy="-7.22021709928097E-05"
        ixz="-4.12551874446929E-09"
        iyy="0.000748014171707252"
        iyz="-1.87143171821543E-08"
        izz="0.000757773817375614" />
    </inertial>
    <visual>
      <origin
        xyz="0 0 0"
        rpy="0 0 0" />
      <geometry>
        <mesh
          filename="package://duco_gcr5_910_urdf/meshes/link1.STL" />
      </geometry>
      <material
        name="">
        <color
          rgba="0.792156862745098 0.819607843137255 0.933333333333333 1" />
      </material>
    </visual>
    <collision>
      <origin
        xyz="0 0 0"
        rpy="0 0 0" />
      <geometry>
        <mesh
          filename="package://duco_gcr5_910_urdf/meshes/link1.STL" />
      </geometry>
    </collision>
  </link>
  <joint
    name="joint1"
    type="continuous">
    <origin
      xyz="0 0 0"
      rpy="1.5707963267949 -1.5707963267949 0" />
    <parent
      link="base_link" />
    <child
      link="link1" />
    <axis
      xyz="-1 0 0" />
  </joint>
  <link
    name="link2">
    <inertial>
      <origin
        xyz="0.134183947911483 0.212437906522792 2.31820817047102E-06"
        rpy="0 0 0" />
      <mass
        value="1.1009274409569" />
      <inertia
        ixx="0.0055456395347035"
        ixy="7.62961559668095E-08"
        ixz="-2.14049084739424E-08"
        iyy="0.00196578079804957"
        iyz="-1.79428640279421E-08"
        izz="0.00501514572024218" />
    </inertial>
    <visual>
      <origin
        xyz="0 0 0"
        rpy="0 0 0" />
      <geometry>
        <mesh
          filename="package://duco_gcr5_910_urdf/meshes/link2.STL" />
      </geometry>
      <material
        name="">
        <color
          rgba="0.792156862745098 0.819607843137255 0.933333333333333 1" />
      </material>
    </visual>
    <collision>
      <origin
        xyz="0 0 0"
        rpy="0 0 0" />
      <geometry>
        <mesh
          filename="package://duco_gcr5_910_urdf/meshes/link2.STL" />
      </geometry>
    </collision>
  </link>
  <joint
    name="joint2"
    type="continuous">
    <origin
      xyz="0.122 0.0052441786897741 0"
      rpy="3.14159265358979 0 1.5707963267949" />
    <parent
      link="link1" />
    <child
      link="link2" />
    <axis
      xyz="-1 0 0" />
  </joint>
  <link
    name="link3">
    <inertial>
      <origin
        xyz="0.0113516317961539 0.205293059413378 6.72059695834408E-07"
        rpy="0 0 0" />
      <mass
        value="0.330047321805258" />
      <inertia
        ixx="0.00115279796036324"
        ixy="3.99615005743179E-06"
        ixz="-2.56815270522183E-09"
        iyy="0.000492028306999432"
        iyz="6.85834293348772E-09"
        izz="0.00111415925904173" />
    </inertial>
    <visual>
      <origin
        xyz="0 0 0"
        rpy="0 0 0" />
      <geometry>
        <mesh
          filename="package://duco_gcr5_910_urdf/meshes/link3.STL" />
      </geometry>
      <material
        name="">
        <color
          rgba="0.792156862745098 0.819607843137255 0.933333333333333 1" />
      </material>
    </visual>
    <collision>
      <origin
        xyz="0 0 0"
        rpy="0 0 0" />
      <geometry>
        <mesh
          filename="package://duco_gcr5_910_urdf/meshes/link3.STL" />
      </geometry>
    </collision>
  </link>
  <joint
    name="joint3"
    type="continuous">
    <origin
      xyz="0 0.425000000002073 0"
      rpy="0 0 0" />
    <parent
      link="link2" />
    <child
      link="link3" />
    <axis
      xyz="-1 0 0" />
  </joint>
  <link
    name="link4">
    <inertial>
      <origin
        xyz="-0.0258799818041116 -0.0924706939539425 -2.19691744333841E-06"
        rpy="0 0 0" />
      <mass
        value="0.165023508277068" />
      <inertia
        ixx="0.000186694412962851"
        ixy="-1.53095845611684E-05"
        ixz="2.75842761285596E-09"
        iyy="0.000162480388600535"
        iyz="-7.90196252051589E-10"
        izz="0.000151979522541323" />
    </inertial>
    <visual>
      <origin
        xyz="0 0 0"
        rpy="0 0 0" />
      <geometry>
        <mesh
          filename="package://duco_gcr5_910_urdf/meshes/link4.STL" />
      </geometry>
      <material
        name="">
        <color
          rgba="0.792156862745098 0.819607843137255 0.933333333333333 1" />
      </material>
    </visual>
    <collision>
      <origin
        xyz="0 0 0"
        rpy="0 0 0" />
      <geometry>
        <mesh
          filename="package://duco_gcr5_910_urdf/meshes/link4.STL" />
      </geometry>
    </collision>
  </link>
  <joint
    name="joint4"
    type="continuous">
    <origin
      xyz="0.018076 0.392 0"
      rpy="3.1416 0 -1.5708" />
    <parent
      link="link3" />
    <child
      link="link4" />
    <axis
      xyz="0 -1 0" />
  </joint>
  <link
    name="link5">
    <inertial>
      <origin
        xyz="-1.94384120312198E-06 -0.00700056668485562 -0.113976527728292"
        rpy="0 0 0" />
      <mass
        value="0.148290193529033" />
      <inertia
        ixx="0.000138012123695848"
        ixy="-3.19096354371036E-09"
        ixz="-8.91486110338573E-10"
        iyy="0.000148488146672156"
        iyz="1.53048362477331E-05"
        izz="0.000163210791571703" />
    </inertial>
    <visual>
      <origin
        xyz="0 0 0"
        rpy="0 0 0" />
      <geometry>
        <mesh
          filename="package://duco_gcr5_910_urdf/meshes/link5.STL" />
      </geometry>
      <material
        name="">
        <color
          rgba="0.792156862745098 0.819607843137255 0.933333333333333 1" />
      </material>
    </visual>
    <collision>
      <origin
        xyz="0 0 0"
        rpy="0 0 0" />
      <geometry>
        <mesh
          filename="package://duco_gcr5_910_urdf/meshes/link5.STL" />
      </geometry>
    </collision>
  </link>
  <joint
    name="joint5"
    type="continuous">
    <origin
      xyz="-0.0027576 -0.08618 0"
      rpy="3.1416 -1.5708 0" />
    <parent
      link="link4" />
    <child
      link="link5" />
    <axis
      xyz="0 0 1" />
  </joint>
  <link
    name="link6">
    <inertial>
      <origin
        xyz="2.34165896569554E-05 -0.0266268928917058 6.87422856384678E-05"
        rpy="0 0 0" />
      <mass
        value="0.270719809445498" />
      <inertia
        ixx="0.000141068608434019"
        ixy="3.17358160794649E-10"
        ixz="-1.97887421997623E-09"
        iyy="0.000209132460882027"
        iyz="9.39235484158471E-08"
        izz="0.000140908406562175" />
    </inertial>
    <visual>
      <origin
        xyz="0 0 0"
        rpy="0 0 0" />
      <geometry>
        <mesh
          filename="package://duco_gcr5_910_urdf/meshes/link6.STL" />
      </geometry>
      <material
        name="">
        <color
          rgba="0.792156862745098 0.819607843137255 0.933333333333333 1" />
      </material>
    </visual>
    <collision>
      <origin
        xyz="0 0 0"
        rpy="0 0 0" />
      <geometry>
        <mesh
          filename="package://duco_gcr5_910_urdf/meshes/link6.STL" />
      </geometry>
    </collision>
  </link>
  <joint
    name="joint6"
    type="continuous">
    <origin
      xyz="0 0.047999999999999 -0.128242442033315"
      rpy="0 0 -3.14159265358979" />
    <parent
      link="link5" />
    <child
      link="link6" />
    <axis
      xyz="0 -1 0" />
  </joint>
</robot>